<?xml version="1.0"?>
<robot xmlns:xacro="http://www.ros.org/wiki/xacro" name="navis">

  <!-- Base parameters -->
  <xacro:property name="base_length" value="0.42" />
  <xacro:property name="base_width" value="0.31" />
  <xacro:property name="base_height" value="0.184" />
  <xacro:property name="base_mass" value="16.524" />
  <xacro:property name="wheel_radius" value="0.098" />
  <xacro:property name="wheel_length" value="0.04" />
  <xacro:property name="wheel_mass" value="0.477" />

  <!-- Base link -->
  <link name="base_link">
    <inertial>
      <origin xyz="0.011999 0.002 0.066996" rpy="0 0 0"/>
      <mass value="${base_mass}"/>
      <inertia
        ixx="0.320605" ixy="-0.000800023" ixz="0.0163992"
        iyy="0.399205" iyz="-0.000900133"
        izz="0.455501"/>
    </inertial>

    <collision name="chassis_collision">
      <origin xyz="0 0 0.092" rpy="0 0 0"/>
      <geometry>
        <box size="${base_length} ${base_width} ${base_height}"/>
      </geometry>
    </collision>

    <visual name="chassis_visual">
      <origin xyz="0 0 -0.0655" rpy="1.5708 0 -1.5708"/>
      <geometry>
        <mesh filename="package://X2/meshes/x2_chassis.dae"/>
      </geometry>
    </visual>
  </link>

    <!-- IMU -->
    <xacro:navis_imu parent="base_link"/>
    <xacro:macro name="navis_imu" params="">
      <link name="imu_link">
        <visual>
          <geometry>
            <box size="0.05 0.05 0.02"/>
          </geometry>
          <material name="gray"/>
        </visual>
        <inertial>
          <mass value="0.01"/>
          <origin xyz="0 0 0" rpy="0 0 0"/>
          <inertia ixx="0.0001" ixy="0.0" ixz="0.0"
                  iyy="0.0001" iyz="0.0"
                  izz="0.0001"/>
        </inertial>
      </link>

      <joint name="imu_joint" type="fixed">
        <parent link="base_link"/>
        <child link="imu_link"/>
        <origin xyz="0 0 0.1" rpy="0 0 0"/>
      </joint>
    </xacro:macro>

    <!-- Visual elements -->
    <!-- <visual name="navsat_visual_1">
      <origin xyz="-0.18 0.126 0.1895" rpy="0 0 0"/>
      <geometry>
        <cylinder length="0.016" radius="0.026"/>
      </geometry>
    </visual> -->

    <!-- Headlights -->
    <xacro:macro name="headlight" params="name xyz rpy">
      <visual name="${name}">
        <origin xyz="${xyz}" rpy="${rpy}"/>
        <geometry>
          <mesh filename="package://X2/meshes/headlight.dae"/>
        </geometry>
      </visual>
    </xacro:macro>

    <xacro:headlight name="center_left_headlight_visual" 
      xyz="0.22 0.05 0.0845" rpy="0 0 -3.14159"/>
    <xacro:headlight name="left_headlight_visual" 
      xyz="0.22 0.145 0.0845" rpy="0 0 -3.14159"/>
    <xacro:headlight name="center_right_headlight_visual" 
      xyz="0.22 -0.05 0.0845" rpy="0 0 -3.14159"/>
    <xacro:headlight name="right_headlight_visual" 
      xyz="0.22 -0.145 0.0845" rpy="0 0 -3.14159"/>
  </link>

  <!-- Wheel macro -->
  <xacro:macro name="wheel" params="prefix xyz reflect">
    <link name="${prefix}_wheel">
      <inertial>
        <mass value="${wheel_mass}"/>
        <inertia
          ixx="0.0013" ixy="0" ixz="0"
          iyy="0.0024" iyz="0"
          izz="0.0013"/>
      </inertial>
      
      <collision name="${prefix}_collision">
        <origin xyz="0 0 0" rpy="1.5708 0 0"/>
        <geometry>
          <cylinder radius="${wheel_radius}" length="${wheel_length}"/>
        </geometry>
        <surface>
          <friction>
            <ode mu="1" mu2="1" slip1="0.0026" slip2="0"/>
          </friction>
        </surface>
      </collision>
      
      <visual name="${prefix}_visual">
        <origin xyz="0 0 0" rpy="1.5708 0 0"/>
        <geometry>
          <mesh filename="package://X2/meshes/x2_wheel_${'left' if reflect > 0 else 'right'}.dae"/>
        </geometry>
      </visual>
    </link>
    
    <joint name="${prefix}_wheel_joint" type="continuous">
      <parent link="base_link"/>
      <child link="${prefix}_wheel"/>
      <origin xyz="${xyz}" rpy="0 0 0"/>
      <axis xyz="0 1 0"/>
    </joint>
    
    <transmission name="${prefix}_wheel_trans">
      <type>transmission_interface/SimpleTransmission</type>
      <joint name="${prefix}_wheel_joint">
        <hardwareInterface>hardware_interface/VelocityJointInterface</hardwareInterface>
      </joint>
      <actuator name="${prefix}_wheel_motor">
        <hardwareInterface>hardware_interface/VelocityJointInterface</hardwareInterface>
        <mechanicalReduction>1</mechanicalReduction>
      </actuator>
    </transmission>
  </xacro:macro>

  <!-- Create wheels -->
  <xacro:wheel prefix="front_left" xyz="0.131 0.187795 0.0345" reflect="1"/>
  <xacro:wheel prefix="front_right" xyz="0.131 -0.187795 0.0345" reflect="-1"/>
  <xacro:wheel prefix="rear_left" xyz="-0.131 0.187795 0.0345" reflect="1"/>
  <xacro:wheel prefix="rear_right" xyz="-0.131 -0.187795 0.0345" reflect="-1"/>

  <!-- Gazebo extensions -->
  <gazebo>
    <plugin name="gazebo_ros_control" filename="libgazebo_ros_control.so">
      <robotNamespace>/X2</robotNamespace>
    </plugin>
  </gazebo>

  <gazebo reference="base_link">
    <mu1>0.2</mu1>
    <mu2>0.2</mu2>
    <material>Gazebo/Grey</material>
  </gazebo>

  <link name="world"/>
    <joint name="world_joint" type="fixed">
      <parent link="world"/>
      <child link="base_link"/>
       <origin xyz="0 0 0" rpy="0 0 0"/>
    </joint>
</robot>